Internal Server Error: /endpoint
Traceback (most recent call last):
  File "/usr/local/lib/python3.8/site-packages/django/core/handlers/exception.py", line 47, in inner
    response = get_response(request)
  File "/usr/local/lib/python3.8/site-packages/django/core/handlers/base.py", line 181, in _get_response
    response = wrapped_callback(request, *callback_args, **callback_kwargs)
  File "/usr/local/lib/python3.8/site-packages/django/views/generic/base.py", line 70, in view
    return self.dispatch(request, *args, **kwargs)
  File "/usr/local/lib/python3.8/site-packages/django/utils/decorators.py", line 43, in _wrapper
    return bound_method(*args, **kwargs)
  File "/usr/local/lib/python3.8/site-packages/django/views/decorators/csrf.py", line 54, in wrapped_view
    return view_func(*args, **kwargs)
  File "/usr/local/lib/python3.8/site-packages/braces/views/_forms.py", line 30, in dispatch
    return super(CsrfExemptMixin, self).dispatch(*args, **kwargs)
  File "/usr/local/lib/python3.8/site-packages/django/views/generic/base.py", line 98, in dispatch
    return handler(request, *args, **kwargs)
  File "/srv/redifod/golem/views.py", line 53, in post
    anomaly_ticket, anomaly_info = petition_geni(id_event)
  File "/srv/redifod/golem/helpers.py", line 53, in petition_geni
    'id':json_event['response']['result']['data'][0]['event']['id'],'status':json_event['response']['result']['data'][0]['event']['status'],'severity':json_event['response']['result']['data'][0]['event']['severity']['type'],
KeyError: 'result'
Internal Server Error: /endpoint
Traceback (most recent call last):
  File "/usr/local/lib/python3.8/site-packages/django/core/handlers/exception.py", line 47, in inner
    response = get_response(request)
  File "/usr/local/lib/python3.8/site-packages/django/core/handlers/base.py", line 181, in _get_response
    response = wrapped_callback(request, *callback_args, **callback_kwargs)
  File "/usr/local/lib/python3.8/site-packages/django/views/generic/base.py", line 70, in view
    return self.dispatch(request, *args, **kwargs)
  File "/usr/local/lib/python3.8/site-packages/django/utils/decorators.py", line 43, in _wrapper
    return bound_method(*args, **kwargs)
  File "/usr/local/lib/python3.8/site-packages/django/views/decorators/csrf.py", line 54, in wrapped_view
    return view_func(*args, **kwargs)
  File "/usr/local/lib/python3.8/site-packages/braces/views/_forms.py", line 30, in dispatch
    return super(CsrfExemptMixin, self).dispatch(*args, **kwargs)
  File "/usr/local/lib/python3.8/site-packages/django/views/generic/base.py", line 98, in dispatch
    return handler(request, *args, **kwargs)
  File "/srv/redifod/golem/views.py", line 53, in post
    anomaly_ticket, anomaly_info = petition_geni(id_event)
  File "/srv/redifod/golem/helpers.py", line 53, in petition_geni
    'id':json_event['response']['result']['data'][0]['event']['id'],'status':json_event['response']['result']['data'][0]['event']['status'],'severity':json_event['response']['result']['data'][0]['event']['severity']['type'],
KeyError: 'result'
Internal Server Error: /endpoint
Traceback (most recent call last):
  File "/usr/local/lib/python3.8/site-packages/django/core/handlers/exception.py", line 47, in inner
    response = get_response(request)
  File "/usr/local/lib/python3.8/site-packages/django/core/handlers/base.py", line 181, in _get_response
    response = wrapped_callback(request, *callback_args, **callback_kwargs)
  File "/usr/local/lib/python3.8/site-packages/django/views/generic/base.py", line 70, in view
    return self.dispatch(request, *args, **kwargs)
  File "/usr/local/lib/python3.8/site-packages/django/utils/decorators.py", line 43, in _wrapper
    return bound_method(*args, **kwargs)
  File "/usr/local/lib/python3.8/site-packages/django/views/decorators/csrf.py", line 54, in wrapped_view
    return view_func(*args, **kwargs)
  File "/usr/local/lib/python3.8/site-packages/braces/views/_forms.py", line 30, in dispatch
    return super(CsrfExemptMixin, self).dispatch(*args, **kwargs)
  File "/usr/local/lib/python3.8/site-packages/django/views/generic/base.py", line 98, in dispatch
    return handler(request, *args, **kwargs)
  File "/srv/redifod/golem/views.py", line 53, in post
    anomaly_ticket, anomaly_info = petition_geni(id_event)
  File "/srv/redifod/golem/helpers.py", line 53, in petition_geni
    'id':json_event['response']['result']['data'][0]['event']['id'],'status':json_event['response']['result']['data'][0]['event']['status'],'severity':json_event['response']['result']['data'][0]['event']['severity']['type'],
KeyError: 'result'
Internal Server Error: /endpoint
Traceback (most recent call last):
  File "/usr/local/lib/python3.8/site-packages/django/core/handlers/exception.py", line 47, in inner
    response = get_response(request)
  File "/usr/local/lib/python3.8/site-packages/django/core/handlers/base.py", line 181, in _get_response
    response = wrapped_callback(request, *callback_args, **callback_kwargs)
  File "/usr/local/lib/python3.8/site-packages/django/views/generic/base.py", line 70, in view
    return self.dispatch(request, *args, **kwargs)
  File "/usr/local/lib/python3.8/site-packages/django/utils/decorators.py", line 43, in _wrapper
    return bound_method(*args, **kwargs)
  File "/usr/local/lib/python3.8/site-packages/django/views/decorators/csrf.py", line 54, in wrapped_view
    return view_func(*args, **kwargs)
  File "/usr/local/lib/python3.8/site-packages/braces/views/_forms.py", line 30, in dispatch
    return super(CsrfExemptMixin, self).dispatch(*args, **kwargs)
  File "/usr/local/lib/python3.8/site-packages/django/views/generic/base.py", line 98, in dispatch
    return handler(request, *args, **kwargs)
  File "/srv/redifod/golem/views.py", line 53, in post
    anomaly_ticket, anomaly_info = petition_geni(id_event)
  File "/srv/redifod/golem/helpers.py", line 53, in petition_geni
    'id':json_event['response']['result']['data'][0]['event']['id'],'status':json_event['response']['result']['data'][0]['event']['status'],'severity':json_event['response']['result']['data'][0]['event']['severity']['type'],
KeyError: 'result'
Internal Server Error: /endpoint
Traceback (most recent call last):
  File "/usr/local/lib/python3.8/site-packages/django/core/handlers/exception.py", line 47, in inner
    response = get_response(request)
  File "/usr/local/lib/python3.8/site-packages/django/core/handlers/base.py", line 181, in _get_response
    response = wrapped_callback(request, *callback_args, **callback_kwargs)
  File "/usr/local/lib/python3.8/site-packages/django/views/generic/base.py", line 70, in view
    return self.dispatch(request, *args, **kwargs)
  File "/usr/local/lib/python3.8/site-packages/django/utils/decorators.py", line 43, in _wrapper
    return bound_method(*args, **kwargs)
  File "/usr/local/lib/python3.8/site-packages/django/views/decorators/csrf.py", line 54, in wrapped_view
    return view_func(*args, **kwargs)
  File "/usr/local/lib/python3.8/site-packages/braces/views/_forms.py", line 30, in dispatch
    return super(CsrfExemptMixin, self).dispatch(*args, **kwargs)
  File "/usr/local/lib/python3.8/site-packages/django/views/generic/base.py", line 98, in dispatch
    return handler(request, *args, **kwargs)
  File "/srv/redifod/golem/views.py", line 53, in post
    anomaly_ticket, anomaly_info = petition_geni(id_event)
  File "/srv/redifod/golem/helpers.py", line 53, in petition_geni
    'id':json_event['response']['result']['data'][0]['event']['id'],'status':json_event['response']['result']['data'][0]['event']['status'],'severity':json_event['response']['result']['data'][0]['event']['severity']['type'],
KeyError: 'result'
Internal Server Error: /endpoint
Traceback (most recent call last):
  File "/usr/local/lib/python3.8/site-packages/django/core/handlers/exception.py", line 47, in inner
    response = get_response(request)
  File "/usr/local/lib/python3.8/site-packages/django/core/handlers/base.py", line 181, in _get_response
    response = wrapped_callback(request, *callback_args, **callback_kwargs)
  File "/usr/local/lib/python3.8/site-packages/django/views/generic/base.py", line 70, in view
    return self.dispatch(request, *args, **kwargs)
  File "/usr/local/lib/python3.8/site-packages/django/utils/decorators.py", line 43, in _wrapper
    return bound_method(*args, **kwargs)
  File "/usr/local/lib/python3.8/site-packages/django/views/decorators/csrf.py", line 54, in wrapped_view
    return view_func(*args, **kwargs)
  File "/usr/local/lib/python3.8/site-packages/braces/views/_forms.py", line 30, in dispatch
    return super(CsrfExemptMixin, self).dispatch(*args, **kwargs)
  File "/usr/local/lib/python3.8/site-packages/django/views/generic/base.py", line 98, in dispatch
    return handler(request, *args, **kwargs)
  File "/srv/redifod/golem/views.py", line 53, in post
    anomaly_ticket, anomaly_info = petition_geni(id_event)
  File "/srv/redifod/golem/helpers.py", line 53, in petition_geni
    'id':json_event['response']['result']['data'][0]['event']['id'],'status':json_event['response']['result']['data'][0]['event']['status'],'severity':json_event['response']['result']['data'][0]['event']['severity']['type'],
KeyError: 'result'
Internal Server Error: /endpoint
Traceback (most recent call last):
  File "/usr/local/lib/python3.8/site-packages/django/core/handlers/exception.py", line 47, in inner
    response = get_response(request)
  File "/usr/local/lib/python3.8/site-packages/django/core/handlers/base.py", line 181, in _get_response
    response = wrapped_callback(request, *callback_args, **callback_kwargs)
  File "/usr/local/lib/python3.8/site-packages/django/views/generic/base.py", line 70, in view
    return self.dispatch(request, *args, **kwargs)
  File "/usr/local/lib/python3.8/site-packages/django/utils/decorators.py", line 43, in _wrapper
    return bound_method(*args, **kwargs)
  File "/usr/local/lib/python3.8/site-packages/django/views/decorators/csrf.py", line 54, in wrapped_view
    return view_func(*args, **kwargs)
  File "/usr/local/lib/python3.8/site-packages/braces/views/_forms.py", line 30, in dispatch
    return super(CsrfExemptMixin, self).dispatch(*args, **kwargs)
  File "/usr/local/lib/python3.8/site-packages/django/views/generic/base.py", line 98, in dispatch
    return handler(request, *args, **kwargs)
  File "/srv/redifod/golem/views.py", line 53, in post
    anomaly_ticket, anomaly_info = petition_geni(id_event)
  File "/srv/redifod/golem/helpers.py", line 53, in petition_geni
    'id':json_event['response']['result']['data'][0]['event']['id'],'status':json_event['response']['result']['data'][0]['event']['status'],'severity':json_event['response']['result']['data'][0]['event']['severity']['type'],
KeyError: 'result'
Internal Server Error: /endpoint
Traceback (most recent call last):
  File "/usr/local/lib/python3.8/site-packages/django/core/handlers/exception.py", line 47, in inner
    response = get_response(request)
  File "/usr/local/lib/python3.8/site-packages/django/core/handlers/base.py", line 181, in _get_response
    response = wrapped_callback(request, *callback_args, **callback_kwargs)
  File "/usr/local/lib/python3.8/site-packages/django/views/generic/base.py", line 70, in view
    return self.dispatch(request, *args, **kwargs)
  File "/usr/local/lib/python3.8/site-packages/django/utils/decorators.py", line 43, in _wrapper
    return bound_method(*args, **kwargs)
  File "/usr/local/lib/python3.8/site-packages/django/views/decorators/csrf.py", line 54, in wrapped_view
    return view_func(*args, **kwargs)
  File "/usr/local/lib/python3.8/site-packages/braces/views/_forms.py", line 30, in dispatch
    return super(CsrfExemptMixin, self).dispatch(*args, **kwargs)
  File "/usr/local/lib/python3.8/site-packages/django/views/generic/base.py", line 98, in dispatch
    return handler(request, *args, **kwargs)
  File "/srv/redifod/golem/views.py", line 53, in post
    anomaly_ticket, anomaly_info = petition_geni(id_event)
  File "/srv/redifod/golem/helpers.py", line 53, in petition_geni
    'id':json_event['response']['result']['data'][0]['event']['id'],'status':json_event['response']['result']['data'][0]['event']['status'],'severity':json_event['response']['result']['data'][0]['event']['severity']['type'],
KeyError: 'result'
Internal Server Error: /endpoint
Traceback (most recent call last):
  File "/usr/local/lib/python3.8/site-packages/django/core/handlers/exception.py", line 47, in inner
    response = get_response(request)
  File "/usr/local/lib/python3.8/site-packages/django/core/handlers/base.py", line 181, in _get_response
    response = wrapped_callback(request, *callback_args, **callback_kwargs)
  File "/usr/local/lib/python3.8/site-packages/django/views/generic/base.py", line 70, in view
    return self.dispatch(request, *args, **kwargs)
  File "/usr/local/lib/python3.8/site-packages/django/utils/decorators.py", line 43, in _wrapper
    return bound_method(*args, **kwargs)
  File "/usr/local/lib/python3.8/site-packages/django/views/decorators/csrf.py", line 54, in wrapped_view
    return view_func(*args, **kwargs)
  File "/usr/local/lib/python3.8/site-packages/braces/views/_forms.py", line 30, in dispatch
    return super(CsrfExemptMixin, self).dispatch(*args, **kwargs)
  File "/usr/local/lib/python3.8/site-packages/django/views/generic/base.py", line 98, in dispatch
    return handler(request, *args, **kwargs)
  File "/srv/redifod/golem/views.py", line 53, in post
    anomaly_ticket, anomaly_info = petition_geni(id_event)
  File "/srv/redifod/golem/helpers.py", line 53, in petition_geni
    'id':json_event['response']['result']['data'][0]['event']['id'],'status':json_event['response']['result']['data'][0]['event']['status'],'severity':json_event['response']['result']['data'][0]['event']['severity']['type'],
KeyError: 'result'
Internal Server Error: /endpoint
Traceback (most recent call last):
  File "/usr/local/lib/python3.8/site-packages/django/core/handlers/exception.py", line 47, in inner
    response = get_response(request)
  File "/usr/local/lib/python3.8/site-packages/django/core/handlers/base.py", line 181, in _get_response
    response = wrapped_callback(request, *callback_args, **callback_kwargs)
  File "/usr/local/lib/python3.8/site-packages/django/views/generic/base.py", line 70, in view
    return self.dispatch(request, *args, **kwargs)
  File "/usr/local/lib/python3.8/site-packages/django/utils/decorators.py", line 43, in _wrapper
    return bound_method(*args, **kwargs)
  File "/usr/local/lib/python3.8/site-packages/django/views/decorators/csrf.py", line 54, in wrapped_view
    return view_func(*args, **kwargs)
  File "/usr/local/lib/python3.8/site-packages/braces/views/_forms.py", line 30, in dispatch
    return super(CsrfExemptMixin, self).dispatch(*args, **kwargs)
  File "/usr/local/lib/python3.8/site-packages/django/views/generic/base.py", line 98, in dispatch
    return handler(request, *args, **kwargs)
  File "/srv/redifod/golem/views.py", line 53, in post
    anomaly_ticket, anomaly_info = petition_geni(id_event)
  File "/srv/redifod/golem/helpers.py", line 53, in petition_geni
    'id':json_event['response']['result']['data'][0]['event']['id'],'status':json_event['response']['result']['data'][0]['event']['status'],'severity':json_event['response']['result']['data'][0]['event']['severity']['type'],
KeyError: 'result'
Internal Server Error: /endpoint
Traceback (most recent call last):
  File "/usr/local/lib/python3.8/site-packages/django/core/handlers/exception.py", line 47, in inner
    response = get_response(request)
  File "/usr/local/lib/python3.8/site-packages/django/core/handlers/base.py", line 181, in _get_response
    response = wrapped_callback(request, *callback_args, **callback_kwargs)
  File "/usr/local/lib/python3.8/site-packages/django/views/generic/base.py", line 70, in view
    return self.dispatch(request, *args, **kwargs)
  File "/usr/local/lib/python3.8/site-packages/django/utils/decorators.py", line 43, in _wrapper
    return bound_method(*args, **kwargs)
  File "/usr/local/lib/python3.8/site-packages/django/views/decorators/csrf.py", line 54, in wrapped_view
    return view_func(*args, **kwargs)
  File "/usr/local/lib/python3.8/site-packages/braces/views/_forms.py", line 30, in dispatch
    return super(CsrfExemptMixin, self).dispatch(*args, **kwargs)
  File "/usr/local/lib/python3.8/site-packages/django/views/generic/base.py", line 98, in dispatch
    return handler(request, *args, **kwargs)
  File "/srv/redifod/golem/views.py", line 53, in post
    anomaly_ticket, anomaly_info = petition_geni(id_event)
  File "/srv/redifod/golem/helpers.py", line 53, in petition_geni
    'id':json_event['response']['result']['data'][0]['event']['id'],'status':json_event['response']['result']['data'][0]['event']['status'],'severity':json_event['response']['result']['data'][0]['event']['severity']['type'],
KeyError: 'result'
Internal Server Error: /endpoint
Traceback (most recent call last):
  File "/usr/local/lib/python3.8/site-packages/django/core/handlers/exception.py", line 47, in inner
    response = get_response(request)
  File "/usr/local/lib/python3.8/site-packages/django/core/handlers/base.py", line 181, in _get_response
    response = wrapped_callback(request, *callback_args, **callback_kwargs)
  File "/usr/local/lib/python3.8/site-packages/django/views/generic/base.py", line 70, in view
    return self.dispatch(request, *args, **kwargs)
  File "/usr/local/lib/python3.8/site-packages/django/utils/decorators.py", line 43, in _wrapper
    return bound_method(*args, **kwargs)
  File "/usr/local/lib/python3.8/site-packages/django/views/decorators/csrf.py", line 54, in wrapped_view
    return view_func(*args, **kwargs)
  File "/usr/local/lib/python3.8/site-packages/braces/views/_forms.py", line 30, in dispatch
    return super(CsrfExemptMixin, self).dispatch(*args, **kwargs)
  File "/usr/local/lib/python3.8/site-packages/django/views/generic/base.py", line 98, in dispatch
    return handler(request, *args, **kwargs)
  File "/srv/redifod/golem/views.py", line 53, in post
    anomaly_ticket, anomaly_info = petition_geni(id_event)
  File "/srv/redifod/golem/helpers.py", line 53, in petition_geni
    'id':json_event['response']['result']['data'][0]['event']['id'],'status':json_event['response']['result']['data'][0]['event']['status'],'severity':json_event['response']['result']['data'][0]['event']['severity']['type'],
KeyError: 'result'
Internal Server Error: /endpoint
Traceback (most recent call last):
  File "/usr/local/lib/python3.8/site-packages/django/core/handlers/exception.py", line 47, in inner
    response = get_response(request)
  File "/usr/local/lib/python3.8/site-packages/django/core/handlers/base.py", line 181, in _get_response
    response = wrapped_callback(request, *callback_args, **callback_kwargs)
  File "/usr/local/lib/python3.8/site-packages/django/views/generic/base.py", line 70, in view
    return self.dispatch(request, *args, **kwargs)
  File "/usr/local/lib/python3.8/site-packages/django/utils/decorators.py", line 43, in _wrapper
    return bound_method(*args, **kwargs)
  File "/usr/local/lib/python3.8/site-packages/django/views/decorators/csrf.py", line 54, in wrapped_view
    return view_func(*args, **kwargs)
  File "/usr/local/lib/python3.8/site-packages/braces/views/_forms.py", line 30, in dispatch
    return super(CsrfExemptMixin, self).dispatch(*args, **kwargs)
  File "/usr/local/lib/python3.8/site-packages/django/views/generic/base.py", line 98, in dispatch
    return handler(request, *args, **kwargs)
  File "/srv/redifod/golem/views.py", line 53, in post
    anomaly_ticket, anomaly_info = petition_geni(id_event)
  File "/srv/redifod/golem/helpers.py", line 53, in petition_geni
    'id':json_event['response']['result']['data'][0]['event']['id'],'status':json_event['response']['result']['data'][0]['event']['status'],'severity':json_event['response']['result']['data'][0]['event']['severity']['type'],
KeyError: 'result'
Internal Server Error: /endpoint
Traceback (most recent call last):
  File "/usr/local/lib/python3.8/site-packages/django/core/handlers/exception.py", line 47, in inner
    response = get_response(request)
  File "/usr/local/lib/python3.8/site-packages/django/core/handlers/base.py", line 181, in _get_response
    response = wrapped_callback(request, *callback_args, **callback_kwargs)
  File "/usr/local/lib/python3.8/site-packages/django/views/generic/base.py", line 70, in view
    return self.dispatch(request, *args, **kwargs)
  File "/usr/local/lib/python3.8/site-packages/django/utils/decorators.py", line 43, in _wrapper
    return bound_method(*args, **kwargs)
  File "/usr/local/lib/python3.8/site-packages/django/views/decorators/csrf.py", line 54, in wrapped_view
    return view_func(*args, **kwargs)
  File "/usr/local/lib/python3.8/site-packages/braces/views/_forms.py", line 30, in dispatch
    return super(CsrfExemptMixin, self).dispatch(*args, **kwargs)
  File "/usr/local/lib/python3.8/site-packages/django/views/generic/base.py", line 98, in dispatch
    return handler(request, *args, **kwargs)
  File "/srv/redifod/golem/views.py", line 53, in post
    anomaly_ticket, anomaly_info = petition_geni(id_event)
  File "/srv/redifod/golem/helpers.py", line 53, in petition_geni
    'id':json_event['response']['result']['data'][0]['event']['id'],'status':json_event['response']['result']['data'][0]['event']['status'],'severity':json_event['response']['result']['data'][0]['event']['severity']['type'],
KeyError: 'result'
Internal Server Error: /endpoint
Traceback (most recent call last):
  File "/usr/local/lib/python3.8/site-packages/django/core/handlers/exception.py", line 47, in inner
    response = get_response(request)
  File "/usr/local/lib/python3.8/site-packages/django/core/handlers/base.py", line 181, in _get_response
    response = wrapped_callback(request, *callback_args, **callback_kwargs)
  File "/usr/local/lib/python3.8/site-packages/django/views/generic/base.py", line 70, in view
    return self.dispatch(request, *args, **kwargs)
  File "/usr/local/lib/python3.8/site-packages/django/utils/decorators.py", line 43, in _wrapper
    return bound_method(*args, **kwargs)
  File "/usr/local/lib/python3.8/site-packages/django/views/decorators/csrf.py", line 54, in wrapped_view
    return view_func(*args, **kwargs)
  File "/usr/local/lib/python3.8/site-packages/braces/views/_forms.py", line 30, in dispatch
    return super(CsrfExemptMixin, self).dispatch(*args, **kwargs)
  File "/usr/local/lib/python3.8/site-packages/django/views/generic/base.py", line 98, in dispatch
    return handler(request, *args, **kwargs)
  File "/srv/redifod/golem/views.py", line 53, in post
    anomaly_ticket, anomaly_info = petition_geni(id_event)
  File "/srv/redifod/golem/helpers.py", line 53, in petition_geni
    'id':json_event['response']['result']['data'][0]['event']['id'],'status':json_event['response']['result']['data'][0]['event']['status'],'severity':json_event['response']['result']['data'][0]['event']['severity']['type'],
KeyError: 'result'
Internal Server Error: /endpoint
Traceback (most recent call last):
  File "/usr/local/lib/python3.8/site-packages/django/core/handlers/exception.py", line 47, in inner
    response = get_response(request)
  File "/usr/local/lib/python3.8/site-packages/django/core/handlers/base.py", line 181, in _get_response
    response = wrapped_callback(request, *callback_args, **callback_kwargs)
  File "/usr/local/lib/python3.8/site-packages/django/views/generic/base.py", line 70, in view
    return self.dispatch(request, *args, **kwargs)
  File "/usr/local/lib/python3.8/site-packages/django/utils/decorators.py", line 43, in _wrapper
    return bound_method(*args, **kwargs)
  File "/usr/local/lib/python3.8/site-packages/django/views/decorators/csrf.py", line 54, in wrapped_view
    return view_func(*args, **kwargs)
  File "/usr/local/lib/python3.8/site-packages/braces/views/_forms.py", line 30, in dispatch
    return super(CsrfExemptMixin, self).dispatch(*args, **kwargs)
  File "/usr/local/lib/python3.8/site-packages/django/views/generic/base.py", line 98, in dispatch
    return handler(request, *args, **kwargs)
  File "/srv/redifod/golem/views.py", line 53, in post
    anomaly_ticket, anomaly_info = petition_geni(id_event)
  File "/srv/redifod/golem/helpers.py", line 53, in petition_geni
    'id':json_event['response']['result']['data'][0]['event']['id'],'status':json_event['response']['result']['data'][0]['event']['status'],'severity':json_event['response']['result']['data'][0]['event']['severity']['type'],
KeyError: 'result'
Internal Server Error: /endpoint
Traceback (most recent call last):
  File "/usr/local/lib/python3.8/site-packages/django/core/handlers/exception.py", line 47, in inner
    response = get_response(request)
  File "/usr/local/lib/python3.8/site-packages/django/core/handlers/base.py", line 181, in _get_response
    response = wrapped_callback(request, *callback_args, **callback_kwargs)
  File "/usr/local/lib/python3.8/site-packages/django/views/generic/base.py", line 70, in view
    return self.dispatch(request, *args, **kwargs)
  File "/usr/local/lib/python3.8/site-packages/django/utils/decorators.py", line 43, in _wrapper
    return bound_method(*args, **kwargs)
  File "/usr/local/lib/python3.8/site-packages/django/views/decorators/csrf.py", line 54, in wrapped_view
    return view_func(*args, **kwargs)
  File "/usr/local/lib/python3.8/site-packages/braces/views/_forms.py", line 30, in dispatch
    return super(CsrfExemptMixin, self).dispatch(*args, **kwargs)
  File "/usr/local/lib/python3.8/site-packages/django/views/generic/base.py", line 98, in dispatch
    return handler(request, *args, **kwargs)
  File "/srv/redifod/golem/views.py", line 53, in post
    anomaly_ticket, anomaly_info = petition_geni(id_event)
  File "/srv/redifod/golem/helpers.py", line 53, in petition_geni
    'id':json_event['response']['result']['data'][0]['event']['id'],'status':json_event['response']['result']['data'][0]['event']['status'],'severity':json_event['response']['result']['data'][0]['event']['severity']['type'],
KeyError: 'result'
Internal Server Error: /endpoint
Traceback (most recent call last):
  File "/usr/local/lib/python3.8/site-packages/django/core/handlers/exception.py", line 47, in inner
    response = get_response(request)
  File "/usr/local/lib/python3.8/site-packages/django/core/handlers/base.py", line 181, in _get_response
    response = wrapped_callback(request, *callback_args, **callback_kwargs)
  File "/usr/local/lib/python3.8/site-packages/django/views/generic/base.py", line 70, in view
    return self.dispatch(request, *args, **kwargs)
  File "/usr/local/lib/python3.8/site-packages/django/utils/decorators.py", line 43, in _wrapper
    return bound_method(*args, **kwargs)
  File "/usr/local/lib/python3.8/site-packages/django/views/decorators/csrf.py", line 54, in wrapped_view
    return view_func(*args, **kwargs)
  File "/usr/local/lib/python3.8/site-packages/braces/views/_forms.py", line 30, in dispatch
    return super(CsrfExemptMixin, self).dispatch(*args, **kwargs)
  File "/usr/local/lib/python3.8/site-packages/django/views/generic/base.py", line 98, in dispatch
    return handler(request, *args, **kwargs)
  File "/srv/redifod/golem/views.py", line 53, in post
    anomaly_ticket, anomaly_info = petition_geni(id_event)
  File "/srv/redifod/golem/helpers.py", line 53, in petition_geni
    'id':json_event['response']['result']['data'][0]['event']['id'],'status':json_event['response']['result']['data'][0]['event']['status'],'severity':json_event['response']['result']['data'][0]['event']['severity']['type'],
KeyError: 'result'
Internal Server Error: /endpoint
Traceback (most recent call last):
  File "/usr/local/lib/python3.8/site-packages/django/core/handlers/exception.py", line 47, in inner
    response = get_response(request)
  File "/usr/local/lib/python3.8/site-packages/django/core/handlers/base.py", line 181, in _get_response
    response = wrapped_callback(request, *callback_args, **callback_kwargs)
  File "/usr/local/lib/python3.8/site-packages/django/views/generic/base.py", line 70, in view
    return self.dispatch(request, *args, **kwargs)
  File "/usr/local/lib/python3.8/site-packages/django/utils/decorators.py", line 43, in _wrapper
    return bound_method(*args, **kwargs)
  File "/usr/local/lib/python3.8/site-packages/django/views/decorators/csrf.py", line 54, in wrapped_view
    return view_func(*args, **kwargs)
  File "/usr/local/lib/python3.8/site-packages/braces/views/_forms.py", line 30, in dispatch
    return super(CsrfExemptMixin, self).dispatch(*args, **kwargs)
  File "/usr/local/lib/python3.8/site-packages/django/views/generic/base.py", line 98, in dispatch
    return handler(request, *args, **kwargs)
  File "/srv/redifod/golem/views.py", line 53, in post
    anomaly_ticket, anomaly_info = petition_geni(id_event)
  File "/srv/redifod/golem/helpers.py", line 53, in petition_geni
    'id':json_event['response']['result']['data'][0]['event']['id'],'status':json_event['response']['result']['data'][0]['event']['status'],'severity':json_event['response']['result']['data'][0]['event']['severity']['type'],
KeyError: 'result'
Internal Server Error: /endpoint
Traceback (most recent call last):
  File "/usr/local/lib/python3.8/site-packages/django/core/handlers/exception.py", line 47, in inner
    response = get_response(request)
  File "/usr/local/lib/python3.8/site-packages/django/core/handlers/base.py", line 181, in _get_response
    response = wrapped_callback(request, *callback_args, **callback_kwargs)
  File "/usr/local/lib/python3.8/site-packages/django/views/generic/base.py", line 70, in view
    return self.dispatch(request, *args, **kwargs)
  File "/usr/local/lib/python3.8/site-packages/django/utils/decorators.py", line 43, in _wrapper
    return bound_method(*args, **kwargs)
  File "/usr/local/lib/python3.8/site-packages/django/views/decorators/csrf.py", line 54, in wrapped_view
    return view_func(*args, **kwargs)
  File "/usr/local/lib/python3.8/site-packages/braces/views/_forms.py", line 30, in dispatch
    return super(CsrfExemptMixin, self).dispatch(*args, **kwargs)
  File "/usr/local/lib/python3.8/site-packages/django/views/generic/base.py", line 98, in dispatch
    return handler(request, *args, **kwargs)
  File "/srv/redifod/golem/views.py", line 53, in post
    anomaly_ticket, anomaly_info = petition_geni(id_event)
  File "/srv/redifod/golem/helpers.py", line 53, in petition_geni
    'id':json_event['response']['result']['data'][0]['event']['id'],'status':json_event['response']['result']['data'][0]['event']['status'],'severity':json_event['response']['result']['data'][0]['event']['severity']['type'],
KeyError: 'result'
Internal Server Error: /endpoint
Traceback (most recent call last):
  File "/usr/local/lib/python3.8/site-packages/django/core/handlers/exception.py", line 47, in inner
    response = get_response(request)
  File "/usr/local/lib/python3.8/site-packages/django/core/handlers/base.py", line 181, in _get_response
    response = wrapped_callback(request, *callback_args, **callback_kwargs)
  File "/usr/local/lib/python3.8/site-packages/django/views/generic/base.py", line 70, in view
    return self.dispatch(request, *args, **kwargs)
  File "/usr/local/lib/python3.8/site-packages/django/utils/decorators.py", line 43, in _wrapper
    return bound_method(*args, **kwargs)
  File "/usr/local/lib/python3.8/site-packages/django/views/decorators/csrf.py", line 54, in wrapped_view
    return view_func(*args, **kwargs)
  File "/usr/local/lib/python3.8/site-packages/braces/views/_forms.py", line 30, in dispatch
    return super(CsrfExemptMixin, self).dispatch(*args, **kwargs)
  File "/usr/local/lib/python3.8/site-packages/django/views/generic/base.py", line 98, in dispatch
    return handler(request, *args, **kwargs)
  File "/srv/redifod/golem/views.py", line 53, in post
    anomaly_ticket, anomaly_info = petition_geni(id_event)
  File "/srv/redifod/golem/helpers.py", line 53, in petition_geni
    'id':json_event['response']['result']['data'][0]['event']['id'],'status':json_event['response']['result']['data'][0]['event']['status'],'severity':json_event['response']['result']['data'][0]['event']['severity']['type'],
KeyError: 'result'
Internal Server Error: /endpoint
Traceback (most recent call last):
  File "/usr/local/lib/python3.8/site-packages/django/core/handlers/exception.py", line 47, in inner
    response = get_response(request)
  File "/usr/local/lib/python3.8/site-packages/django/core/handlers/base.py", line 181, in _get_response
    response = wrapped_callback(request, *callback_args, **callback_kwargs)
  File "/usr/local/lib/python3.8/site-packages/django/views/generic/base.py", line 70, in view
    return self.dispatch(request, *args, **kwargs)
  File "/usr/local/lib/python3.8/site-packages/django/utils/decorators.py", line 43, in _wrapper
    return bound_method(*args, **kwargs)
  File "/usr/local/lib/python3.8/site-packages/django/views/decorators/csrf.py", line 54, in wrapped_view
    return view_func(*args, **kwargs)
  File "/usr/local/lib/python3.8/site-packages/braces/views/_forms.py", line 30, in dispatch
    return super(CsrfExemptMixin, self).dispatch(*args, **kwargs)
  File "/usr/local/lib/python3.8/site-packages/django/views/generic/base.py", line 98, in dispatch
    return handler(request, *args, **kwargs)
  File "/srv/redifod/golem/views.py", line 53, in post
    anomaly_ticket, anomaly_info = petition_geni(id_event)
  File "/srv/redifod/golem/helpers.py", line 53, in petition_geni
    'id':json_event['response']['result']['data'][0]['event']['id'],'status':json_event['response']['result']['data'][0]['event']['status'],'severity':json_event['response']['result']['data'][0]['event']['severity']['type'],
KeyError: 'result'
Internal Server Error: /endpoint
Traceback (most recent call last):
  File "/usr/local/lib/python3.8/site-packages/django/core/handlers/exception.py", line 47, in inner
    response = get_response(request)
  File "/usr/local/lib/python3.8/site-packages/django/core/handlers/base.py", line 181, in _get_response
    response = wrapped_callback(request, *callback_args, **callback_kwargs)
  File "/usr/local/lib/python3.8/site-packages/django/views/generic/base.py", line 70, in view
    return self.dispatch(request, *args, **kwargs)
  File "/usr/local/lib/python3.8/site-packages/django/utils/decorators.py", line 43, in _wrapper
    return bound_method(*args, **kwargs)
  File "/usr/local/lib/python3.8/site-packages/django/views/decorators/csrf.py", line 54, in wrapped_view
    return view_func(*args, **kwargs)
  File "/usr/local/lib/python3.8/site-packages/braces/views/_forms.py", line 30, in dispatch
    return super(CsrfExemptMixin, self).dispatch(*args, **kwargs)
  File "/usr/local/lib/python3.8/site-packages/django/views/generic/base.py", line 98, in dispatch
    return handler(request, *args, **kwargs)
  File "/srv/redifod/golem/views.py", line 53, in post
    anomaly_ticket, anomaly_info = petition_geni(id_event)
  File "/srv/redifod/golem/helpers.py", line 53, in petition_geni
    'id':json_event['response']['result']['data'][0]['event']['id'],'status':json_event['response']['result']['data'][0]['event']['status'],'severity':json_event['response']['result']['data'][0]['event']['severity']['type'],
KeyError: 'result'
Internal Server Error: /endpoint
Traceback (most recent call last):
  File "/usr/local/lib/python3.8/site-packages/django/core/handlers/exception.py", line 47, in inner
    response = get_response(request)
  File "/usr/local/lib/python3.8/site-packages/django/core/handlers/base.py", line 181, in _get_response
    response = wrapped_callback(request, *callback_args, **callback_kwargs)
  File "/usr/local/lib/python3.8/site-packages/django/views/generic/base.py", line 70, in view
    return self.dispatch(request, *args, **kwargs)
  File "/usr/local/lib/python3.8/site-packages/django/utils/decorators.py", line 43, in _wrapper
    return bound_method(*args, **kwargs)
  File "/usr/local/lib/python3.8/site-packages/django/views/decorators/csrf.py", line 54, in wrapped_view
    return view_func(*args, **kwargs)
  File "/usr/local/lib/python3.8/site-packages/braces/views/_forms.py", line 30, in dispatch
    return super(CsrfExemptMixin, self).dispatch(*args, **kwargs)
  File "/usr/local/lib/python3.8/site-packages/django/views/generic/base.py", line 98, in dispatch
    return handler(request, *args, **kwargs)
  File "/srv/redifod/golem/views.py", line 53, in post
    anomaly_ticket, anomaly_info = petition_geni(id_event)
  File "/srv/redifod/golem/helpers.py", line 53, in petition_geni
    'id':json_event['response']['result']['data'][0]['event']['id'],'status':json_event['response']['result']['data'][0]['event']['status'],'severity':json_event['response']['result']['data'][0]['event']['severity']['type'],
KeyError: 'result'
Internal Server Error: /endpoint
Traceback (most recent call last):
  File "/usr/local/lib/python3.8/site-packages/django/core/handlers/exception.py", line 47, in inner
    response = get_response(request)
  File "/usr/local/lib/python3.8/site-packages/django/core/handlers/base.py", line 181, in _get_response
    response = wrapped_callback(request, *callback_args, **callback_kwargs)
  File "/usr/local/lib/python3.8/site-packages/django/views/generic/base.py", line 70, in view
    return self.dispatch(request, *args, **kwargs)
  File "/usr/local/lib/python3.8/site-packages/django/utils/decorators.py", line 43, in _wrapper
    return bound_method(*args, **kwargs)
  File "/usr/local/lib/python3.8/site-packages/django/views/decorators/csrf.py", line 54, in wrapped_view
    return view_func(*args, **kwargs)
  File "/usr/local/lib/python3.8/site-packages/braces/views/_forms.py", line 30, in dispatch
    return super(CsrfExemptMixin, self).dispatch(*args, **kwargs)
  File "/usr/local/lib/python3.8/site-packages/django/views/generic/base.py", line 98, in dispatch
    return handler(request, *args, **kwargs)
  File "/srv/redifod/golem/views.py", line 53, in post
    anomaly_ticket, anomaly_info = petition_geni(id_event)
  File "/srv/redifod/golem/helpers.py", line 53, in petition_geni
    'id':json_event['response']['result']['data'][0]['event']['id'],'status':json_event['response']['result']['data'][0]['event']['status'],'severity':json_event['response']['result']['data'][0]['event']['severity']['type'],
KeyError: 'result'
Internal Server Error: /endpoint
Traceback (most recent call last):
  File "/usr/local/lib/python3.8/site-packages/django/core/handlers/exception.py", line 47, in inner
    response = get_response(request)
  File "/usr/local/lib/python3.8/site-packages/django/core/handlers/base.py", line 181, in _get_response
    response = wrapped_callback(request, *callback_args, **callback_kwargs)
  File "/usr/local/lib/python3.8/site-packages/django/views/generic/base.py", line 70, in view
    return self.dispatch(request, *args, **kwargs)
  File "/usr/local/lib/python3.8/site-packages/django/utils/decorators.py", line 43, in _wrapper
    return bound_method(*args, **kwargs)
  File "/usr/local/lib/python3.8/site-packages/django/views/decorators/csrf.py", line 54, in wrapped_view
    return view_func(*args, **kwargs)
  File "/usr/local/lib/python3.8/site-packages/braces/views/_forms.py", line 30, in dispatch
    return super(CsrfExemptMixin, self).dispatch(*args, **kwargs)
  File "/usr/local/lib/python3.8/site-packages/django/views/generic/base.py", line 98, in dispatch
    return handler(request, *args, **kwargs)
  File "/srv/redifod/golem/views.py", line 53, in post
    anomaly_ticket, anomaly_info = petition_geni(id_event)
  File "/srv/redifod/golem/helpers.py", line 53, in petition_geni
    'id':json_event['response']['result']['data'][0]['event']['id'],'status':json_event['response']['result']['data'][0]['event']['status'],'severity':json_event['response']['result']['data'][0]['event']['severity']['type'],
KeyError: 'result'
Internal Server Error: /endpoint
Traceback (most recent call last):
  File "/usr/local/lib/python3.8/site-packages/django/core/handlers/exception.py", line 47, in inner
    response = get_response(request)
  File "/usr/local/lib/python3.8/site-packages/django/core/handlers/base.py", line 181, in _get_response
    response = wrapped_callback(request, *callback_args, **callback_kwargs)
  File "/usr/local/lib/python3.8/site-packages/django/views/generic/base.py", line 70, in view
    return self.dispatch(request, *args, **kwargs)
  File "/usr/local/lib/python3.8/site-packages/django/utils/decorators.py", line 43, in _wrapper
    return bound_method(*args, **kwargs)
  File "/usr/local/lib/python3.8/site-packages/django/views/decorators/csrf.py", line 54, in wrapped_view
    return view_func(*args, **kwargs)
  File "/usr/local/lib/python3.8/site-packages/braces/views/_forms.py", line 30, in dispatch
    return super(CsrfExemptMixin, self).dispatch(*args, **kwargs)
  File "/usr/local/lib/python3.8/site-packages/django/views/generic/base.py", line 98, in dispatch
    return handler(request, *args, **kwargs)
  File "/srv/redifod/golem/views.py", line 53, in post
    anomaly_ticket, anomaly_info = petition_geni(id_event)
  File "/srv/redifod/golem/helpers.py", line 53, in petition_geni
    'id':json_event['response']['result']['data'][0]['event']['id'],'status':json_event['response']['result']['data'][0]['event']['status'],'severity':json_event['response']['result']['data'][0]['event']['severity']['type'],
KeyError: 'result'
Internal Server Error: /endpoint
Traceback (most recent call last):
  File "/usr/local/lib/python3.8/site-packages/django/core/handlers/exception.py", line 47, in inner
    response = get_response(request)
  File "/usr/local/lib/python3.8/site-packages/django/core/handlers/base.py", line 181, in _get_response
    response = wrapped_callback(request, *callback_args, **callback_kwargs)
  File "/usr/local/lib/python3.8/site-packages/django/views/generic/base.py", line 70, in view
    return self.dispatch(request, *args, **kwargs)
  File "/usr/local/lib/python3.8/site-packages/django/utils/decorators.py", line 43, in _wrapper
    return bound_method(*args, **kwargs)
  File "/usr/local/lib/python3.8/site-packages/django/views/decorators/csrf.py", line 54, in wrapped_view
    return view_func(*args, **kwargs)
  File "/usr/local/lib/python3.8/site-packages/braces/views/_forms.py", line 30, in dispatch
    return super(CsrfExemptMixin, self).dispatch(*args, **kwargs)
  File "/usr/local/lib/python3.8/site-packages/django/views/generic/base.py", line 98, in dispatch
    return handler(request, *args, **kwargs)
  File "/srv/redifod/golem/views.py", line 53, in post
    anomaly_ticket, anomaly_info = petition_geni(id_event)
  File "/srv/redifod/golem/helpers.py", line 53, in petition_geni
    'id':json_event['response']['result']['data'][0]['event']['id'],'status':json_event['response']['result']['data'][0]['event']['status'],'severity':json_event['response']['result']['data'][0]['event']['severity']['type'],
KeyError: 'result'
Internal Server Error: /endpoint
Traceback (most recent call last):
  File "/usr/local/lib/python3.8/site-packages/django/core/handlers/exception.py", line 47, in inner
    response = get_response(request)
  File "/usr/local/lib/python3.8/site-packages/django/core/handlers/base.py", line 181, in _get_response
    response = wrapped_callback(request, *callback_args, **callback_kwargs)
  File "/usr/local/lib/python3.8/site-packages/django/views/generic/base.py", line 70, in view
    return self.dispatch(request, *args, **kwargs)
  File "/usr/local/lib/python3.8/site-packages/django/utils/decorators.py", line 43, in _wrapper
    return bound_method(*args, **kwargs)
  File "/usr/local/lib/python3.8/site-packages/django/views/decorators/csrf.py", line 54, in wrapped_view
    return view_func(*args, **kwargs)
  File "/usr/local/lib/python3.8/site-packages/braces/views/_forms.py", line 30, in dispatch
    return super(CsrfExemptMixin, self).dispatch(*args, **kwargs)
  File "/usr/local/lib/python3.8/site-packages/django/views/generic/base.py", line 98, in dispatch
    return handler(request, *args, **kwargs)
  File "/srv/redifod/golem/views.py", line 53, in post
    anomaly_ticket, anomaly_info = petition_geni(id_event)
  File "/srv/redifod/golem/helpers.py", line 53, in petition_geni
    'id':json_event['response']['result']['data'][0]['event']['id'],'status':json_event['response']['result']['data'][0]['event']['status'],'severity':json_event['response']['result']['data'][0]['event']['severity']['type'],
KeyError: 'result'
Internal Server Error: /endpoint
Traceback (most recent call last):
  File "/usr/local/lib/python3.8/site-packages/django/core/handlers/exception.py", line 47, in inner
    response = get_response(request)
  File "/usr/local/lib/python3.8/site-packages/django/core/handlers/base.py", line 181, in _get_response
    response = wrapped_callback(request, *callback_args, **callback_kwargs)
  File "/usr/local/lib/python3.8/site-packages/django/views/generic/base.py", line 70, in view
    return self.dispatch(request, *args, **kwargs)
  File "/usr/local/lib/python3.8/site-packages/django/utils/decorators.py", line 43, in _wrapper
    return bound_method(*args, **kwargs)
  File "/usr/local/lib/python3.8/site-packages/django/views/decorators/csrf.py", line 54, in wrapped_view
    return view_func(*args, **kwargs)
  File "/usr/local/lib/python3.8/site-packages/braces/views/_forms.py", line 30, in dispatch
    return super(CsrfExemptMixin, self).dispatch(*args, **kwargs)
  File "/usr/local/lib/python3.8/site-packages/django/views/generic/base.py", line 98, in dispatch
    return handler(request, *args, **kwargs)
  File "/srv/redifod/golem/views.py", line 53, in post
    anomaly_ticket, anomaly_info = petition_geni(id_event)
  File "/srv/redifod/golem/helpers.py", line 53, in petition_geni
    'id':json_event['response']['result']['data'][0]['event']['id'],'status':json_event['response']['result']['data'][0]['event']['status'],'severity':json_event['response']['result']['data'][0]['event']['severity']['type'],
KeyError: 'result'
Internal Server Error: /endpoint
Traceback (most recent call last):
  File "/usr/local/lib/python3.8/site-packages/django/core/handlers/exception.py", line 47, in inner
    response = get_response(request)
  File "/usr/local/lib/python3.8/site-packages/django/core/handlers/base.py", line 181, in _get_response
    response = wrapped_callback(request, *callback_args, **callback_kwargs)
  File "/usr/local/lib/python3.8/site-packages/django/views/generic/base.py", line 70, in view
    return self.dispatch(request, *args, **kwargs)
  File "/usr/local/lib/python3.8/site-packages/django/utils/decorators.py", line 43, in _wrapper
    return bound_method(*args, **kwargs)
  File "/usr/local/lib/python3.8/site-packages/django/views/decorators/csrf.py", line 54, in wrapped_view
    return view_func(*args, **kwargs)
  File "/usr/local/lib/python3.8/site-packages/braces/views/_forms.py", line 30, in dispatch
    return super(CsrfExemptMixin, self).dispatch(*args, **kwargs)
  File "/usr/local/lib/python3.8/site-packages/django/views/generic/base.py", line 98, in dispatch
    return handler(request, *args, **kwargs)
  File "/srv/redifod/golem/views.py", line 53, in post
    anomaly_ticket, anomaly_info = petition_geni(id_event)
  File "/srv/redifod/golem/helpers.py", line 53, in petition_geni
    'id':json_event['response']['result']['data'][0]['event']['id'],'status':json_event['response']['result']['data'][0]['event']['status'],'severity':json_event['response']['result']['data'][0]['event']['severity']['type'],
KeyError: 'result'
Internal Server Error: /endpoint
Traceback (most recent call last):
  File "/usr/local/lib/python3.8/site-packages/django/core/handlers/exception.py", line 47, in inner
    response = get_response(request)
  File "/usr/local/lib/python3.8/site-packages/django/core/handlers/base.py", line 181, in _get_response
    response = wrapped_callback(request, *callback_args, **callback_kwargs)
  File "/usr/local/lib/python3.8/site-packages/django/views/generic/base.py", line 70, in view
    return self.dispatch(request, *args, **kwargs)
  File "/usr/local/lib/python3.8/site-packages/django/utils/decorators.py", line 43, in _wrapper
    return bound_method(*args, **kwargs)
  File "/usr/local/lib/python3.8/site-packages/django/views/decorators/csrf.py", line 54, in wrapped_view
    return view_func(*args, **kwargs)
  File "/usr/local/lib/python3.8/site-packages/braces/views/_forms.py", line 30, in dispatch
    return super(CsrfExemptMixin, self).dispatch(*args, **kwargs)
  File "/usr/local/lib/python3.8/site-packages/django/views/generic/base.py", line 98, in dispatch
    return handler(request, *args, **kwargs)
  File "/srv/redifod/golem/views.py", line 53, in post
    anomaly_ticket, anomaly_info = petition_geni(id_event)
  File "/srv/redifod/golem/helpers.py", line 53, in petition_geni
    'id':json_event['response']['result']['data'][0]['event']['id'],'status':json_event['response']['result']['data'][0]['event']['status'],'severity':json_event['response']['result']['data'][0]['event']['severity']['type'],
KeyError: 'result'
Internal Server Error: /endpoint
Traceback (most recent call last):
  File "/usr/local/lib/python3.8/site-packages/django/core/handlers/exception.py", line 47, in inner
    response = get_response(request)
  File "/usr/local/lib/python3.8/site-packages/django/core/handlers/base.py", line 181, in _get_response
    response = wrapped_callback(request, *callback_args, **callback_kwargs)
  File "/usr/local/lib/python3.8/site-packages/django/views/generic/base.py", line 70, in view
    return self.dispatch(request, *args, **kwargs)
  File "/usr/local/lib/python3.8/site-packages/django/utils/decorators.py", line 43, in _wrapper
    return bound_method(*args, **kwargs)
  File "/usr/local/lib/python3.8/site-packages/django/views/decorators/csrf.py", line 54, in wrapped_view
    return view_func(*args, **kwargs)
  File "/usr/local/lib/python3.8/site-packages/braces/views/_forms.py", line 30, in dispatch
    return super(CsrfExemptMixin, self).dispatch(*args, **kwargs)
  File "/usr/local/lib/python3.8/site-packages/django/views/generic/base.py", line 98, in dispatch
    return handler(request, *args, **kwargs)
  File "/srv/redifod/golem/views.py", line 53, in post
    anomaly_ticket, anomaly_info = petition_geni(id_event)
  File "/srv/redifod/golem/helpers.py", line 53, in petition_geni
    'id':json_event['response']['result']['data'][0]['event']['id'],'status':json_event['response']['result']['data'][0]['event']['status'],'severity':json_event['response']['result']['data'][0]['event']['severity']['type'],
KeyError: 'result'
Internal Server Error: /endpoint
Traceback (most recent call last):
  File "/usr/local/lib/python3.8/site-packages/django/core/handlers/exception.py", line 47, in inner
    response = get_response(request)
  File "/usr/local/lib/python3.8/site-packages/django/core/handlers/base.py", line 181, in _get_response
    response = wrapped_callback(request, *callback_args, **callback_kwargs)
  File "/usr/local/lib/python3.8/site-packages/django/views/generic/base.py", line 70, in view
    return self.dispatch(request, *args, **kwargs)
  File "/usr/local/lib/python3.8/site-packages/django/utils/decorators.py", line 43, in _wrapper
    return bound_method(*args, **kwargs)
  File "/usr/local/lib/python3.8/site-packages/django/views/decorators/csrf.py", line 54, in wrapped_view
    return view_func(*args, **kwargs)
  File "/usr/local/lib/python3.8/site-packages/braces/views/_forms.py", line 30, in dispatch
    return super(CsrfExemptMixin, self).dispatch(*args, **kwargs)
  File "/usr/local/lib/python3.8/site-packages/django/views/generic/base.py", line 98, in dispatch
    return handler(request, *args, **kwargs)
  File "/srv/redifod/golem/views.py", line 53, in post
    anomaly_ticket, anomaly_info = petition_geni(id_event)
  File "/srv/redifod/golem/helpers.py", line 53, in petition_geni
    'id':json_event['response']['result']['data'][0]['event']['id'],'status':json_event['response']['result']['data'][0]['event']['status'],'severity':json_event['response']['result']['data'][0]['event']['severity']['type'],
KeyError: 'result'
Internal Server Error: /endpoint
Traceback (most recent call last):
  File "/usr/local/lib/python3.8/site-packages/django/core/handlers/exception.py", line 47, in inner
    response = get_response(request)
  File "/usr/local/lib/python3.8/site-packages/django/core/handlers/base.py", line 181, in _get_response
    response = wrapped_callback(request, *callback_args, **callback_kwargs)
  File "/usr/local/lib/python3.8/site-packages/django/views/generic/base.py", line 70, in view
    return self.dispatch(request, *args, **kwargs)
  File "/usr/local/lib/python3.8/site-packages/django/utils/decorators.py", line 43, in _wrapper
    return bound_method(*args, **kwargs)
  File "/usr/local/lib/python3.8/site-packages/django/views/decorators/csrf.py", line 54, in wrapped_view
    return view_func(*args, **kwargs)
  File "/usr/local/lib/python3.8/site-packages/braces/views/_forms.py", line 30, in dispatch
    return super(CsrfExemptMixin, self).dispatch(*args, **kwargs)
  File "/usr/local/lib/python3.8/site-packages/django/views/generic/base.py", line 98, in dispatch
    return handler(request, *args, **kwargs)
  File "/srv/redifod/golem/views.py", line 53, in post
    anomaly_ticket, anomaly_info = petition_geni(id_event)
  File "/srv/redifod/golem/helpers.py", line 53, in petition_geni
    'id':json_event['response']['result']['data'][0]['event']['id'],'status':json_event['response']['result']['data'][0]['event']['status'],'severity':json_event['response']['result']['data'][0]['event']['severity']['type'],
KeyError: 'result'
Internal Server Error: /endpoint
Traceback (most recent call last):
  File "/usr/local/lib/python3.8/site-packages/django/core/handlers/exception.py", line 47, in inner
    response = get_response(request)
  File "/usr/local/lib/python3.8/site-packages/django/core/handlers/base.py", line 181, in _get_response
    response = wrapped_callback(request, *callback_args, **callback_kwargs)
  File "/usr/local/lib/python3.8/site-packages/django/views/generic/base.py", line 70, in view
    return self.dispatch(request, *args, **kwargs)
  File "/usr/local/lib/python3.8/site-packages/django/utils/decorators.py", line 43, in _wrapper
    return bound_method(*args, **kwargs)
  File "/usr/local/lib/python3.8/site-packages/django/views/decorators/csrf.py", line 54, in wrapped_view
    return view_func(*args, **kwargs)
  File "/usr/local/lib/python3.8/site-packages/braces/views/_forms.py", line 30, in dispatch
    return super(CsrfExemptMixin, self).dispatch(*args, **kwargs)
  File "/usr/local/lib/python3.8/site-packages/django/views/generic/base.py", line 98, in dispatch
    return handler(request, *args, **kwargs)
  File "/srv/redifod/golem/views.py", line 53, in post
    anomaly_ticket, anomaly_info = petition_geni(id_event)
  File "/srv/redifod/golem/helpers.py", line 53, in petition_geni
    'id':json_event['response']['result']['data'][0]['event']['id'],'status':json_event['response']['result']['data'][0]['event']['status'],'severity':json_event['response']['result']['data'][0]['event']['severity']['type'],
KeyError: 'result'
Internal Server Error: /endpoint
Traceback (most recent call last):
  File "/usr/local/lib/python3.8/site-packages/django/core/handlers/exception.py", line 47, in inner
    response = get_response(request)
  File "/usr/local/lib/python3.8/site-packages/django/core/handlers/base.py", line 181, in _get_response
    response = wrapped_callback(request, *callback_args, **callback_kwargs)
  File "/usr/local/lib/python3.8/site-packages/django/views/generic/base.py", line 70, in view
    return self.dispatch(request, *args, **kwargs)
  File "/usr/local/lib/python3.8/site-packages/django/utils/decorators.py", line 43, in _wrapper
    return bound_method(*args, **kwargs)
  File "/usr/local/lib/python3.8/site-packages/django/views/decorators/csrf.py", line 54, in wrapped_view
    return view_func(*args, **kwargs)
  File "/usr/local/lib/python3.8/site-packages/braces/views/_forms.py", line 30, in dispatch
    return super(CsrfExemptMixin, self).dispatch(*args, **kwargs)
  File "/usr/local/lib/python3.8/site-packages/django/views/generic/base.py", line 98, in dispatch
    return handler(request, *args, **kwargs)
  File "/srv/redifod/golem/views.py", line 53, in post
    anomaly_ticket, anomaly_info = petition_geni(id_event)
  File "/srv/redifod/golem/helpers.py", line 53, in petition_geni
    'id':json_event['response']['result']['data'][0]['event']['id'],'status':json_event['response']['result']['data'][0]['event']['status'],'severity':json_event['response']['result']['data'][0]['event']['severity']['type'],
KeyError: 'result'
Internal Server Error: /endpoint
Traceback (most recent call last):
  File "/srv/redifod/golem/views.py", line 54, in post
    anomaly_ticket, anomaly_info = petition_geni(id_event)
  File "/srv/redifod/golem/helpers.py", line 53, in petition_geni
    'id':json_event['response']['result']['data'][0]['event']['id'],'status':json_event['response']['result']['data'][0]['event']['status'],'severity':json_event['response']['result']['data'][0]['event']['severity']['type'],
KeyError: 'result'

During handling of the above exception, another exception occurred:

Traceback (most recent call last):
  File "/usr/local/lib/python3.8/site-packages/django/core/handlers/exception.py", line 47, in inner
    response = get_response(request)
  File "/usr/local/lib/python3.8/site-packages/django/core/handlers/base.py", line 181, in _get_response
    response = wrapped_callback(request, *callback_args, **callback_kwargs)
  File "/usr/local/lib/python3.8/site-packages/django/views/generic/base.py", line 70, in view
    return self.dispatch(request, *args, **kwargs)
  File "/usr/local/lib/python3.8/site-packages/django/utils/decorators.py", line 43, in _wrapper
    return bound_method(*args, **kwargs)
  File "/usr/local/lib/python3.8/site-packages/django/views/decorators/csrf.py", line 54, in wrapped_view
    return view_func(*args, **kwargs)
  File "/usr/local/lib/python3.8/site-packages/braces/views/_forms.py", line 30, in dispatch
    return super(CsrfExemptMixin, self).dispatch(*args, **kwargs)
  File "/usr/local/lib/python3.8/site-packages/django/views/generic/base.py", line 98, in dispatch
    return handler(request, *args, **kwargs)
  File "/srv/redifod/golem/views.py", line 56, in post
    logger.ingo('There has been an error while trying to analyze the golem event.')
AttributeError: 'Logger' object has no attribute 'ingo'
Internal Server Error: /endpoint
Traceback (most recent call last):
  File "/srv/redifod/golem/views.py", line 54, in post
    anomaly_ticket, anomaly_info = petition_geni(id_event)
  File "/srv/redifod/golem/helpers.py", line 53, in petition_geni
    'id':json_event['response']['result']['data'][0]['event']['id'],'status':json_event['response']['result']['data'][0]['event']['status'],'severity':json_event['response']['result']['data'][0]['event']['severity']['type'],
KeyError: 'result'

During handling of the above exception, another exception occurred:

Traceback (most recent call last):
  File "/usr/local/lib/python3.8/site-packages/django/core/handlers/exception.py", line 47, in inner
    response = get_response(request)
  File "/usr/local/lib/python3.8/site-packages/django/core/handlers/base.py", line 181, in _get_response
    response = wrapped_callback(request, *callback_args, **callback_kwargs)
  File "/usr/local/lib/python3.8/site-packages/django/views/generic/base.py", line 70, in view
    return self.dispatch(request, *args, **kwargs)
  File "/usr/local/lib/python3.8/site-packages/django/utils/decorators.py", line 43, in _wrapper
    return bound_method(*args, **kwargs)
  File "/usr/local/lib/python3.8/site-packages/django/views/decorators/csrf.py", line 54, in wrapped_view
    return view_func(*args, **kwargs)
  File "/usr/local/lib/python3.8/site-packages/braces/views/_forms.py", line 30, in dispatch
    return super(CsrfExemptMixin, self).dispatch(*args, **kwargs)
  File "/usr/local/lib/python3.8/site-packages/django/views/generic/base.py", line 98, in dispatch
    return handler(request, *args, **kwargs)
  File "/srv/redifod/golem/views.py", line 56, in post
    logger.ingo('There has been an error while trying to analyze the golem event.')
AttributeError: 'Logger' object has no attribute 'ingo'
Internal Server Error: /endpoint
Traceback (most recent call last):
  File "/srv/redifod/golem/views.py", line 54, in post
    anomaly_ticket, anomaly_info = petition_geni(id_event)
  File "/srv/redifod/golem/helpers.py", line 53, in petition_geni
    'id':json_event['response']['result']['data'][0]['event']['id'],'status':json_event['response']['result']['data'][0]['event']['status'],'severity':json_event['response']['result']['data'][0]['event']['severity']['type'],
KeyError: 'result'

During handling of the above exception, another exception occurred:

Traceback (most recent call last):
  File "/usr/local/lib/python3.8/site-packages/django/core/handlers/exception.py", line 47, in inner
    response = get_response(request)
  File "/usr/local/lib/python3.8/site-packages/django/core/handlers/base.py", line 181, in _get_response
    response = wrapped_callback(request, *callback_args, **callback_kwargs)
  File "/usr/local/lib/python3.8/site-packages/django/views/generic/base.py", line 70, in view
    return self.dispatch(request, *args, **kwargs)
  File "/usr/local/lib/python3.8/site-packages/django/utils/decorators.py", line 43, in _wrapper
    return bound_method(*args, **kwargs)
  File "/usr/local/lib/python3.8/site-packages/django/views/decorators/csrf.py", line 54, in wrapped_view
    return view_func(*args, **kwargs)
  File "/usr/local/lib/python3.8/site-packages/braces/views/_forms.py", line 30, in dispatch
    return super(CsrfExemptMixin, self).dispatch(*args, **kwargs)
  File "/usr/local/lib/python3.8/site-packages/django/views/generic/base.py", line 98, in dispatch
    return handler(request, *args, **kwargs)
  File "/srv/redifod/golem/views.py", line 56, in post
    logger.ingo('There has been an error while trying to analyze the golem event.')
AttributeError: 'Logger' object has no attribute 'ingo'
